[2020-07-07 19:36:05,702] {taskinstance.py:669} INFO - Dependencies all met for <TaskInstance: covid_stats.extract 2020-06-28T00:00:00+00:00 [queued]>
[2020-07-07 19:36:05,711] {taskinstance.py:669} INFO - Dependencies all met for <TaskInstance: covid_stats.extract 2020-06-28T00:00:00+00:00 [queued]>
[2020-07-07 19:36:05,711] {taskinstance.py:879} INFO - 
--------------------------------------------------------------------------------
[2020-07-07 19:36:05,711] {taskinstance.py:880} INFO - Starting attempt 6 of 6
[2020-07-07 19:36:05,712] {taskinstance.py:881} INFO - 
--------------------------------------------------------------------------------
[2020-07-07 19:36:05,723] {taskinstance.py:900} INFO - Executing <Task(PythonOperator): extract> on 2020-06-28T00:00:00+00:00
[2020-07-07 19:36:05,728] {standard_task_runner.py:53} INFO - Started process 6588 to run task
[2020-07-07 19:36:05,784] {logging_mixin.py:112} INFO - Running %s on host %s <TaskInstance: covid_stats.extract 2020-06-28T00:00:00+00:00 [running]> nineleaps-ThinkPad-E480
[2020-07-07 19:36:05,802] {taskinstance.py:1145} ERROR - HTTPSConnectionPool(host='api.covid19india.org', port=443): Max retries exceeded with url: /states_daily.json (Caused by NewConnectionError('<urllib3.connection.HTTPSConnection object at 0x7fa2358c3950>: Failed to establish a new connection: [Errno -2] Name or service not known',))
Traceback (most recent call last):
  File "/home/nineleaps/.local/lib/python2.7/site-packages/airflow/models/taskinstance.py", line 983, in _run_raw_task
    result = task_copy.execute(context=context)
  File "/home/nineleaps/.local/lib/python2.7/site-packages/airflow/operators/python_operator.py", line 113, in execute
    return_value = self.execute_callable()
  File "/home/nineleaps/.local/lib/python2.7/site-packages/airflow/operators/python_operator.py", line 118, in execute_callable
    return self.python_callable(*self.op_args, **self.op_kwargs)
  File "/home/nineleaps/airflow/plugins/extract.py", line 16, in extract
    res = requests.get(API_URL)
  File "/home/nineleaps/.local/lib/python2.7/site-packages/requests/api.py", line 76, in get
    return request('get', url, params=params, **kwargs)
  File "/home/nineleaps/.local/lib/python2.7/site-packages/requests/api.py", line 61, in request
    return session.request(method=method, url=url, **kwargs)
  File "/home/nineleaps/.local/lib/python2.7/site-packages/requests/sessions.py", line 530, in request
    resp = self.send(prep, **send_kwargs)
  File "/home/nineleaps/.local/lib/python2.7/site-packages/requests/sessions.py", line 643, in send
    r = adapter.send(request, **kwargs)
  File "/home/nineleaps/.local/lib/python2.7/site-packages/requests/adapters.py", line 516, in send
    raise ConnectionError(e, request=request)
ConnectionError: HTTPSConnectionPool(host='api.covid19india.org', port=443): Max retries exceeded with url: /states_daily.json (Caused by NewConnectionError('<urllib3.connection.HTTPSConnection object at 0x7fa2358c3950>: Failed to establish a new connection: [Errno -2] Name or service not known',))
[2020-07-07 19:36:05,803] {taskinstance.py:1187} INFO - All retries failed; marking task as FAILED.dag_id=covid_stats, task_id=extract, execution_date=20200628T000000, start_date=20200707T140605, end_date=20200707T140605
[2020-07-07 19:36:15,701] {logging_mixin.py:112} INFO - [2020-07-07 19:36:15,700] {local_task_job.py:103} INFO - Task exited with return code 1
