[2020-06-29 12:51:52,994] {taskinstance.py:669} INFO - Dependencies all met for <TaskInstance: covid_stats.validate_and_clean_data 2020-06-29T00:00:00+00:00 [queued]>
[2020-06-29 12:51:53,005] {taskinstance.py:669} INFO - Dependencies all met for <TaskInstance: covid_stats.validate_and_clean_data 2020-06-29T00:00:00+00:00 [queued]>
[2020-06-29 12:51:53,005] {taskinstance.py:879} INFO - 
--------------------------------------------------------------------------------
[2020-06-29 12:51:53,005] {taskinstance.py:880} INFO - Starting attempt 1 of 6
[2020-06-29 12:51:53,005] {taskinstance.py:881} INFO - 
--------------------------------------------------------------------------------
[2020-06-29 12:51:53,012] {taskinstance.py:900} INFO - Executing <Task(PythonOperator): validate_and_clean_data> on 2020-06-29T00:00:00+00:00
[2020-06-29 12:51:53,014] {standard_task_runner.py:53} INFO - Started process 3926 to run task
[2020-06-29 12:51:53,049] {logging_mixin.py:112} INFO - Running %s on host %s <TaskInstance: covid_stats.validate_and_clean_data 2020-06-29T00:00:00+00:00 [running]> nineleaps-ThinkPad-E480
[2020-06-29 12:51:53,062] {taskinstance.py:1145} ERROR - 'date'
Traceback (most recent call last):
  File "/home/nineleaps/.local/lib/python2.7/site-packages/airflow/models/taskinstance.py", line 983, in _run_raw_task
    result = task_copy.execute(context=context)
  File "/home/nineleaps/.local/lib/python2.7/site-packages/airflow/operators/python_operator.py", line 113, in execute
    return_value = self.execute_callable()
  File "/home/nineleaps/.local/lib/python2.7/site-packages/airflow/operators/python_operator.py", line 118, in execute_callable
    return self.python_callable(*self.op_args, **self.op_kwargs)
  File "/home/nineleaps/airflow/plugins/validate_and_clean_data.py", line 30, in validate_and_clean_data
    pandas_df['date'] = pd.to_datetime(pandas_df['date'], format="%d-%b-%y").dt.date
  File "/home/nineleaps/.local/lib/python2.7/site-packages/pandas/core/frame.py", line 2927, in __getitem__
    indexer = self.columns.get_loc(key)
  File "/home/nineleaps/.local/lib/python2.7/site-packages/pandas/core/indexes/base.py", line 2659, in get_loc
    return self._engine.get_loc(self._maybe_cast_indexer(key))
  File "pandas/_libs/index.pyx", line 108, in pandas._libs.index.IndexEngine.get_loc
  File "pandas/_libs/index.pyx", line 132, in pandas._libs.index.IndexEngine.get_loc
  File "pandas/_libs/hashtable_class_helper.pxi", line 1601, in pandas._libs.hashtable.PyObjectHashTable.get_item
  File "pandas/_libs/hashtable_class_helper.pxi", line 1608, in pandas._libs.hashtable.PyObjectHashTable.get_item
KeyError: 'date'
[2020-06-29 12:51:53,069] {taskinstance.py:1168} INFO - Marking task as UP_FOR_RETRY
[2020-06-29 12:52:02,992] {logging_mixin.py:112} INFO - [2020-06-29 12:52:02,991] {local_task_job.py:103} INFO - Task exited with return code 1
