[2020-06-28 19:40:47,747] {taskinstance.py:669} INFO - Dependencies all met for <TaskInstance: covid_stats.validate_and_clean_data 2020-06-27T00:00:00+00:00 [queued]>
[2020-06-28 19:40:47,759] {taskinstance.py:669} INFO - Dependencies all met for <TaskInstance: covid_stats.validate_and_clean_data 2020-06-27T00:00:00+00:00 [queued]>
[2020-06-28 19:40:47,759] {taskinstance.py:879} INFO - 
--------------------------------------------------------------------------------
[2020-06-28 19:40:47,759] {taskinstance.py:880} INFO - Starting attempt 1 of 6
[2020-06-28 19:40:47,759] {taskinstance.py:881} INFO - 
--------------------------------------------------------------------------------
[2020-06-28 19:40:47,767] {taskinstance.py:900} INFO - Executing <Task(PythonOperator): validate_and_clean_data> on 2020-06-27T00:00:00+00:00
[2020-06-28 19:40:47,769] {standard_task_runner.py:53} INFO - Started process 9761 to run task
[2020-06-28 19:40:47,807] {logging_mixin.py:112} INFO - Running %s on host %s <TaskInstance: covid_stats.validate_and_clean_data 2020-06-27T00:00:00+00:00 [running]> nineleaps-ThinkPad-E480
[2020-06-28 19:40:47,821] {taskinstance.py:1145} ERROR - 'date'
Traceback (most recent call last):
  File "/home/nineleaps/.local/lib/python2.7/site-packages/airflow/models/taskinstance.py", line 983, in _run_raw_task
    result = task_copy.execute(context=context)
  File "/home/nineleaps/.local/lib/python2.7/site-packages/airflow/operators/python_operator.py", line 113, in execute
    return_value = self.execute_callable()
  File "/home/nineleaps/.local/lib/python2.7/site-packages/airflow/operators/python_operator.py", line 118, in execute_callable
    return self.python_callable(*self.op_args, **self.op_kwargs)
  File "/home/nineleaps/airflow/plugins/validate_and_clean_data.py", line 30, in validate_and_clean_data
    pandas_df['date'] = pd.to_datetime(pandas_df['date'], format="%d-%b-%y").dt.date
  File "/home/nineleaps/.local/lib/python2.7/site-packages/pandas/core/frame.py", line 2927, in __getitem__
    indexer = self.columns.get_loc(key)
  File "/home/nineleaps/.local/lib/python2.7/site-packages/pandas/core/indexes/base.py", line 2659, in get_loc
    return self._engine.get_loc(self._maybe_cast_indexer(key))
  File "pandas/_libs/index.pyx", line 108, in pandas._libs.index.IndexEngine.get_loc
  File "pandas/_libs/index.pyx", line 132, in pandas._libs.index.IndexEngine.get_loc
  File "pandas/_libs/hashtable_class_helper.pxi", line 1601, in pandas._libs.hashtable.PyObjectHashTable.get_item
  File "pandas/_libs/hashtable_class_helper.pxi", line 1608, in pandas._libs.hashtable.PyObjectHashTable.get_item
KeyError: 'date'
[2020-06-28 19:40:47,825] {taskinstance.py:1168} INFO - Marking task as UP_FOR_RETRY
[2020-06-28 19:40:57,751] {logging_mixin.py:112} INFO - [2020-06-28 19:40:57,751] {local_task_job.py:103} INFO - Task exited with return code 1
[2020-06-28 19:50:35,766] {taskinstance.py:669} INFO - Dependencies all met for <TaskInstance: covid_stats.validate_and_clean_data 2020-06-27T00:00:00+00:00 [queued]>
[2020-06-28 19:50:35,776] {taskinstance.py:669} INFO - Dependencies all met for <TaskInstance: covid_stats.validate_and_clean_data 2020-06-27T00:00:00+00:00 [queued]>
[2020-06-28 19:50:35,776] {taskinstance.py:879} INFO - 
--------------------------------------------------------------------------------
[2020-06-28 19:50:35,776] {taskinstance.py:880} INFO - Starting attempt 1 of 6
[2020-06-28 19:50:35,776] {taskinstance.py:881} INFO - 
--------------------------------------------------------------------------------
[2020-06-28 19:50:35,782] {taskinstance.py:900} INFO - Executing <Task(PythonOperator): validate_and_clean_data> on 2020-06-27T00:00:00+00:00
[2020-06-28 19:50:35,784] {standard_task_runner.py:53} INFO - Started process 13915 to run task
[2020-06-28 19:50:35,822] {logging_mixin.py:112} INFO - Running %s on host %s <TaskInstance: covid_stats.validate_and_clean_data 2020-06-27T00:00:00+00:00 [running]> nineleaps-ThinkPad-E480
[2020-06-28 19:50:35,836] {taskinstance.py:1145} ERROR - 'date'
Traceback (most recent call last):
  File "/home/nineleaps/.local/lib/python2.7/site-packages/airflow/models/taskinstance.py", line 983, in _run_raw_task
    result = task_copy.execute(context=context)
  File "/home/nineleaps/.local/lib/python2.7/site-packages/airflow/operators/python_operator.py", line 113, in execute
    return_value = self.execute_callable()
  File "/home/nineleaps/.local/lib/python2.7/site-packages/airflow/operators/python_operator.py", line 118, in execute_callable
    return self.python_callable(*self.op_args, **self.op_kwargs)
  File "/home/nineleaps/airflow/plugins/validate_and_clean_data.py", line 30, in validate_and_clean_data
    pandas_df['date'] = pd.to_datetime(pandas_df['date'], format="%d-%b-%y").dt.date
  File "/home/nineleaps/.local/lib/python2.7/site-packages/pandas/core/frame.py", line 2927, in __getitem__
    indexer = self.columns.get_loc(key)
  File "/home/nineleaps/.local/lib/python2.7/site-packages/pandas/core/indexes/base.py", line 2659, in get_loc
    return self._engine.get_loc(self._maybe_cast_indexer(key))
  File "pandas/_libs/index.pyx", line 108, in pandas._libs.index.IndexEngine.get_loc
  File "pandas/_libs/index.pyx", line 132, in pandas._libs.index.IndexEngine.get_loc
  File "pandas/_libs/hashtable_class_helper.pxi", line 1601, in pandas._libs.hashtable.PyObjectHashTable.get_item
  File "pandas/_libs/hashtable_class_helper.pxi", line 1608, in pandas._libs.hashtable.PyObjectHashTable.get_item
KeyError: 'date'
[2020-06-28 19:50:35,839] {taskinstance.py:1168} INFO - Marking task as UP_FOR_RETRY
[2020-06-28 19:50:45,765] {logging_mixin.py:112} INFO - [2020-06-28 19:50:45,764] {local_task_job.py:103} INFO - Task exited with return code 1
[2020-06-28 20:02:10,761] {taskinstance.py:669} INFO - Dependencies all met for <TaskInstance: covid_stats.validate_and_clean_data 2020-06-27T00:00:00+00:00 [queued]>
[2020-06-28 20:02:10,772] {taskinstance.py:669} INFO - Dependencies all met for <TaskInstance: covid_stats.validate_and_clean_data 2020-06-27T00:00:00+00:00 [queued]>
[2020-06-28 20:02:10,772] {taskinstance.py:879} INFO - 
--------------------------------------------------------------------------------
[2020-06-28 20:02:10,772] {taskinstance.py:880} INFO - Starting attempt 1 of 6
[2020-06-28 20:02:10,772] {taskinstance.py:881} INFO - 
--------------------------------------------------------------------------------
[2020-06-28 20:02:10,780] {taskinstance.py:900} INFO - Executing <Task(PythonOperator): validate_and_clean_data> on 2020-06-27T00:00:00+00:00
[2020-06-28 20:02:10,784] {standard_task_runner.py:53} INFO - Started process 4319 to run task
[2020-06-28 20:02:10,828] {logging_mixin.py:112} INFO - Running %s on host %s <TaskInstance: covid_stats.validate_and_clean_data 2020-06-27T00:00:00+00:00 [running]> nineleaps-ThinkPad-E480
[2020-06-28 20:02:10,841] {taskinstance.py:1145} ERROR - 'date'
Traceback (most recent call last):
  File "/home/nineleaps/.local/lib/python2.7/site-packages/airflow/models/taskinstance.py", line 983, in _run_raw_task
    result = task_copy.execute(context=context)
  File "/home/nineleaps/.local/lib/python2.7/site-packages/airflow/operators/python_operator.py", line 113, in execute
    return_value = self.execute_callable()
  File "/home/nineleaps/.local/lib/python2.7/site-packages/airflow/operators/python_operator.py", line 118, in execute_callable
    return self.python_callable(*self.op_args, **self.op_kwargs)
  File "/home/nineleaps/airflow/plugins/validate_and_clean_data.py", line 30, in validate_and_clean_data
    pandas_df['date'] = pd.to_datetime(pandas_df['date'], format="%d-%m-%y").dt.date
  File "/home/nineleaps/.local/lib/python2.7/site-packages/pandas/core/frame.py", line 2927, in __getitem__
    indexer = self.columns.get_loc(key)
  File "/home/nineleaps/.local/lib/python2.7/site-packages/pandas/core/indexes/base.py", line 2659, in get_loc
    return self._engine.get_loc(self._maybe_cast_indexer(key))
  File "pandas/_libs/index.pyx", line 108, in pandas._libs.index.IndexEngine.get_loc
  File "pandas/_libs/index.pyx", line 132, in pandas._libs.index.IndexEngine.get_loc
  File "pandas/_libs/hashtable_class_helper.pxi", line 1601, in pandas._libs.hashtable.PyObjectHashTable.get_item
  File "pandas/_libs/hashtable_class_helper.pxi", line 1608, in pandas._libs.hashtable.PyObjectHashTable.get_item
KeyError: 'date'
[2020-06-28 20:02:10,848] {taskinstance.py:1168} INFO - Marking task as UP_FOR_RETRY
[2020-06-28 20:02:20,751] {logging_mixin.py:112} INFO - [2020-06-28 20:02:20,750] {local_task_job.py:103} INFO - Task exited with return code 1
[2020-06-28 20:10:21,251] {taskinstance.py:669} INFO - Dependencies all met for <TaskInstance: covid_stats.validate_and_clean_data 2020-06-27T00:00:00+00:00 [queued]>
[2020-06-28 20:10:21,260] {taskinstance.py:669} INFO - Dependencies all met for <TaskInstance: covid_stats.validate_and_clean_data 2020-06-27T00:00:00+00:00 [queued]>
[2020-06-28 20:10:21,261] {taskinstance.py:879} INFO - 
--------------------------------------------------------------------------------
[2020-06-28 20:10:21,261] {taskinstance.py:880} INFO - Starting attempt 1 of 6
[2020-06-28 20:10:21,261] {taskinstance.py:881} INFO - 
--------------------------------------------------------------------------------
[2020-06-28 20:10:21,267] {taskinstance.py:900} INFO - Executing <Task(PythonOperator): validate_and_clean_data> on 2020-06-27T00:00:00+00:00
[2020-06-28 20:10:21,269] {standard_task_runner.py:53} INFO - Started process 8324 to run task
[2020-06-28 20:10:21,303] {logging_mixin.py:112} INFO - Running %s on host %s <TaskInstance: covid_stats.validate_and_clean_data 2020-06-27T00:00:00+00:00 [running]> nineleaps-ThinkPad-E480
[2020-06-28 20:10:21,316] {taskinstance.py:1145} ERROR - 'date'
Traceback (most recent call last):
  File "/home/nineleaps/.local/lib/python2.7/site-packages/airflow/models/taskinstance.py", line 983, in _run_raw_task
    result = task_copy.execute(context=context)
  File "/home/nineleaps/.local/lib/python2.7/site-packages/airflow/operators/python_operator.py", line 113, in execute
    return_value = self.execute_callable()
  File "/home/nineleaps/.local/lib/python2.7/site-packages/airflow/operators/python_operator.py", line 118, in execute_callable
    return self.python_callable(*self.op_args, **self.op_kwargs)
  File "/home/nineleaps/airflow/plugins/validate_and_clean_data.py", line 30, in validate_and_clean_data
    pandas_df['date'] = pd.to_datetime(pandas_df['date'], format="%d-%m-%y").dt.date
  File "/home/nineleaps/.local/lib/python2.7/site-packages/pandas/core/frame.py", line 2927, in __getitem__
    indexer = self.columns.get_loc(key)
  File "/home/nineleaps/.local/lib/python2.7/site-packages/pandas/core/indexes/base.py", line 2659, in get_loc
    return self._engine.get_loc(self._maybe_cast_indexer(key))
  File "pandas/_libs/index.pyx", line 108, in pandas._libs.index.IndexEngine.get_loc
  File "pandas/_libs/index.pyx", line 132, in pandas._libs.index.IndexEngine.get_loc
  File "pandas/_libs/hashtable_class_helper.pxi", line 1601, in pandas._libs.hashtable.PyObjectHashTable.get_item
  File "pandas/_libs/hashtable_class_helper.pxi", line 1608, in pandas._libs.hashtable.PyObjectHashTable.get_item
KeyError: 'date'
[2020-06-28 20:10:21,319] {taskinstance.py:1168} INFO - Marking task as UP_FOR_RETRY
[2020-06-28 20:10:31,253] {logging_mixin.py:112} INFO - [2020-06-28 20:10:31,252] {local_task_job.py:103} INFO - Task exited with return code 1
[2020-06-28 20:25:02,688] {taskinstance.py:669} INFO - Dependencies all met for <TaskInstance: covid_stats.validate_and_clean_data 2020-06-27T00:00:00+00:00 [queued]>
[2020-06-28 20:25:02,697] {taskinstance.py:669} INFO - Dependencies all met for <TaskInstance: covid_stats.validate_and_clean_data 2020-06-27T00:00:00+00:00 [queued]>
[2020-06-28 20:25:02,697] {taskinstance.py:879} INFO - 
--------------------------------------------------------------------------------
[2020-06-28 20:25:02,698] {taskinstance.py:880} INFO - Starting attempt 1 of 6
[2020-06-28 20:25:02,698] {taskinstance.py:881} INFO - 
--------------------------------------------------------------------------------
[2020-06-28 20:25:02,704] {taskinstance.py:900} INFO - Executing <Task(PythonOperator): validate_and_clean_data> on 2020-06-27T00:00:00+00:00
[2020-06-28 20:25:02,707] {standard_task_runner.py:53} INFO - Started process 14529 to run task
[2020-06-28 20:25:02,753] {logging_mixin.py:112} INFO - Running %s on host %s <TaskInstance: covid_stats.validate_and_clean_data 2020-06-27T00:00:00+00:00 [running]> nineleaps-ThinkPad-E480
[2020-06-28 20:25:02,768] {taskinstance.py:1145} ERROR - 'date'
Traceback (most recent call last):
  File "/home/nineleaps/.local/lib/python2.7/site-packages/airflow/models/taskinstance.py", line 983, in _run_raw_task
    result = task_copy.execute(context=context)
  File "/home/nineleaps/.local/lib/python2.7/site-packages/airflow/operators/python_operator.py", line 113, in execute
    return_value = self.execute_callable()
  File "/home/nineleaps/.local/lib/python2.7/site-packages/airflow/operators/python_operator.py", line 118, in execute_callable
    return self.python_callable(*self.op_args, **self.op_kwargs)
  File "/home/nineleaps/airflow/plugins/validate_and_clean_data.py", line 30, in validate_and_clean_data
    pandas_df['date'] = pd.to_datetime(pandas_df['date'], format="%d-%b-%y").dt.date
  File "/home/nineleaps/.local/lib/python2.7/site-packages/pandas/core/frame.py", line 2927, in __getitem__
    indexer = self.columns.get_loc(key)
  File "/home/nineleaps/.local/lib/python2.7/site-packages/pandas/core/indexes/base.py", line 2659, in get_loc
    return self._engine.get_loc(self._maybe_cast_indexer(key))
  File "pandas/_libs/index.pyx", line 108, in pandas._libs.index.IndexEngine.get_loc
  File "pandas/_libs/index.pyx", line 132, in pandas._libs.index.IndexEngine.get_loc
  File "pandas/_libs/hashtable_class_helper.pxi", line 1601, in pandas._libs.hashtable.PyObjectHashTable.get_item
  File "pandas/_libs/hashtable_class_helper.pxi", line 1608, in pandas._libs.hashtable.PyObjectHashTable.get_item
KeyError: 'date'
[2020-06-28 20:25:02,771] {taskinstance.py:1168} INFO - Marking task as UP_FOR_RETRY
[2020-06-28 20:25:12,684] {logging_mixin.py:112} INFO - [2020-06-28 20:25:12,683] {local_task_job.py:103} INFO - Task exited with return code 1
[2020-06-29 11:22:33,986] {taskinstance.py:669} INFO - Dependencies all met for <TaskInstance: covid_stats.validate_and_clean_data 2020-06-27T00:00:00+00:00 [queued]>
[2020-06-29 11:22:33,996] {taskinstance.py:669} INFO - Dependencies all met for <TaskInstance: covid_stats.validate_and_clean_data 2020-06-27T00:00:00+00:00 [queued]>
[2020-06-29 11:22:33,996] {taskinstance.py:879} INFO - 
--------------------------------------------------------------------------------
[2020-06-29 11:22:33,996] {taskinstance.py:880} INFO - Starting attempt 1 of 6
[2020-06-29 11:22:33,996] {taskinstance.py:881} INFO - 
--------------------------------------------------------------------------------
[2020-06-29 11:22:34,004] {taskinstance.py:900} INFO - Executing <Task(PythonOperator): validate_and_clean_data> on 2020-06-27T00:00:00+00:00
[2020-06-29 11:22:34,007] {standard_task_runner.py:53} INFO - Started process 4241 to run task
[2020-06-29 11:22:34,053] {logging_mixin.py:112} INFO - Running %s on host %s <TaskInstance: covid_stats.validate_and_clean_data 2020-06-27T00:00:00+00:00 [running]> nineleaps-ThinkPad-E480
[2020-06-29 11:22:34,067] {taskinstance.py:1145} ERROR - 'date'
Traceback (most recent call last):
  File "/home/nineleaps/.local/lib/python2.7/site-packages/airflow/models/taskinstance.py", line 983, in _run_raw_task
    result = task_copy.execute(context=context)
  File "/home/nineleaps/.local/lib/python2.7/site-packages/airflow/operators/python_operator.py", line 113, in execute
    return_value = self.execute_callable()
  File "/home/nineleaps/.local/lib/python2.7/site-packages/airflow/operators/python_operator.py", line 118, in execute_callable
    return self.python_callable(*self.op_args, **self.op_kwargs)
  File "/home/nineleaps/airflow/plugins/validate_and_clean_data.py", line 30, in validate_and_clean_data
    pandas_df['date'] = pd.to_datetime(pandas_df['date'], format="%d-%b-%y").dt.date
  File "/home/nineleaps/.local/lib/python2.7/site-packages/pandas/core/frame.py", line 2927, in __getitem__
    indexer = self.columns.get_loc(key)
  File "/home/nineleaps/.local/lib/python2.7/site-packages/pandas/core/indexes/base.py", line 2659, in get_loc
    return self._engine.get_loc(self._maybe_cast_indexer(key))
  File "pandas/_libs/index.pyx", line 108, in pandas._libs.index.IndexEngine.get_loc
  File "pandas/_libs/index.pyx", line 132, in pandas._libs.index.IndexEngine.get_loc
  File "pandas/_libs/hashtable_class_helper.pxi", line 1601, in pandas._libs.hashtable.PyObjectHashTable.get_item
  File "pandas/_libs/hashtable_class_helper.pxi", line 1608, in pandas._libs.hashtable.PyObjectHashTable.get_item
KeyError: 'date'
[2020-06-29 11:22:34,073] {taskinstance.py:1168} INFO - Marking task as UP_FOR_RETRY
[2020-06-29 11:22:43,987] {logging_mixin.py:112} INFO - [2020-06-29 11:22:43,986] {local_task_job.py:103} INFO - Task exited with return code 1
[2020-06-29 11:57:41,744] {taskinstance.py:669} INFO - Dependencies all met for <TaskInstance: covid_stats.validate_and_clean_data 2020-06-27T00:00:00+00:00 [queued]>
[2020-06-29 11:57:41,757] {taskinstance.py:669} INFO - Dependencies all met for <TaskInstance: covid_stats.validate_and_clean_data 2020-06-27T00:00:00+00:00 [queued]>
[2020-06-29 11:57:41,757] {taskinstance.py:879} INFO - 
--------------------------------------------------------------------------------
[2020-06-29 11:57:41,757] {taskinstance.py:880} INFO - Starting attempt 1 of 6
[2020-06-29 11:57:41,757] {taskinstance.py:881} INFO - 
--------------------------------------------------------------------------------
[2020-06-29 11:57:41,767] {taskinstance.py:900} INFO - Executing <Task(PythonOperator): validate_and_clean_data> on 2020-06-27T00:00:00+00:00
[2020-06-29 11:57:41,769] {standard_task_runner.py:53} INFO - Started process 3686 to run task
[2020-06-29 11:57:41,819] {logging_mixin.py:112} INFO - Running %s on host %s <TaskInstance: covid_stats.validate_and_clean_data 2020-06-27T00:00:00+00:00 [running]> nineleaps-ThinkPad-E480
[2020-06-29 11:57:41,838] {taskinstance.py:1145} ERROR - 'date'
Traceback (most recent call last):
  File "/home/nineleaps/.local/lib/python2.7/site-packages/airflow/models/taskinstance.py", line 983, in _run_raw_task
    result = task_copy.execute(context=context)
  File "/home/nineleaps/.local/lib/python2.7/site-packages/airflow/operators/python_operator.py", line 113, in execute
    return_value = self.execute_callable()
  File "/home/nineleaps/.local/lib/python2.7/site-packages/airflow/operators/python_operator.py", line 118, in execute_callable
    return self.python_callable(*self.op_args, **self.op_kwargs)
  File "/home/nineleaps/airflow/plugins/validate_and_clean_data.py", line 30, in validate_and_clean_data
    pandas_df['date'] = pd.to_datetime(pandas_df['date'], format="%d-%b-%y").dt.date
  File "/home/nineleaps/.local/lib/python2.7/site-packages/pandas/core/frame.py", line 2927, in __getitem__
    indexer = self.columns.get_loc(key)
  File "/home/nineleaps/.local/lib/python2.7/site-packages/pandas/core/indexes/base.py", line 2659, in get_loc
    return self._engine.get_loc(self._maybe_cast_indexer(key))
  File "pandas/_libs/index.pyx", line 108, in pandas._libs.index.IndexEngine.get_loc
  File "pandas/_libs/index.pyx", line 132, in pandas._libs.index.IndexEngine.get_loc
  File "pandas/_libs/hashtable_class_helper.pxi", line 1601, in pandas._libs.hashtable.PyObjectHashTable.get_item
  File "pandas/_libs/hashtable_class_helper.pxi", line 1608, in pandas._libs.hashtable.PyObjectHashTable.get_item
KeyError: 'date'
[2020-06-29 11:57:41,843] {taskinstance.py:1168} INFO - Marking task as UP_FOR_RETRY
[2020-06-29 11:57:51,742] {logging_mixin.py:112} INFO - [2020-06-29 11:57:51,741] {local_task_job.py:103} INFO - Task exited with return code 1
