[2020-06-28 19:42:05,082] {taskinstance.py:669} INFO - Dependencies all met for <TaskInstance: covid_stats.validate_and_clean_data 2020-06-27T00:00:00+00:00 [queued]>
[2020-06-28 19:42:05,094] {taskinstance.py:669} INFO - Dependencies all met for <TaskInstance: covid_stats.validate_and_clean_data 2020-06-27T00:00:00+00:00 [queued]>
[2020-06-28 19:42:05,094] {taskinstance.py:879} INFO - 
--------------------------------------------------------------------------------
[2020-06-28 19:42:05,094] {taskinstance.py:880} INFO - Starting attempt 2 of 6
[2020-06-28 19:42:05,094] {taskinstance.py:881} INFO - 
--------------------------------------------------------------------------------
[2020-06-28 19:42:05,101] {taskinstance.py:900} INFO - Executing <Task(PythonOperator): validate_and_clean_data> on 2020-06-27T00:00:00+00:00
[2020-06-28 19:42:05,103] {standard_task_runner.py:53} INFO - Started process 10338 to run task
[2020-06-28 19:42:05,140] {logging_mixin.py:112} INFO - Running %s on host %s <TaskInstance: covid_stats.validate_and_clean_data 2020-06-27T00:00:00+00:00 [running]> nineleaps-ThinkPad-E480
[2020-06-28 19:42:05,154] {taskinstance.py:1145} ERROR - 'date'
Traceback (most recent call last):
  File "/home/nineleaps/.local/lib/python2.7/site-packages/airflow/models/taskinstance.py", line 983, in _run_raw_task
    result = task_copy.execute(context=context)
  File "/home/nineleaps/.local/lib/python2.7/site-packages/airflow/operators/python_operator.py", line 113, in execute
    return_value = self.execute_callable()
  File "/home/nineleaps/.local/lib/python2.7/site-packages/airflow/operators/python_operator.py", line 118, in execute_callable
    return self.python_callable(*self.op_args, **self.op_kwargs)
  File "/home/nineleaps/airflow/plugins/validate_and_clean_data.py", line 30, in validate_and_clean_data
    pandas_df['date'] = pd.to_datetime(pandas_df['date'], format="%d-%b-%y").dt.date
  File "/home/nineleaps/.local/lib/python2.7/site-packages/pandas/core/frame.py", line 2927, in __getitem__
    indexer = self.columns.get_loc(key)
  File "/home/nineleaps/.local/lib/python2.7/site-packages/pandas/core/indexes/base.py", line 2659, in get_loc
    return self._engine.get_loc(self._maybe_cast_indexer(key))
  File "pandas/_libs/index.pyx", line 108, in pandas._libs.index.IndexEngine.get_loc
  File "pandas/_libs/index.pyx", line 132, in pandas._libs.index.IndexEngine.get_loc
  File "pandas/_libs/hashtable_class_helper.pxi", line 1601, in pandas._libs.hashtable.PyObjectHashTable.get_item
  File "pandas/_libs/hashtable_class_helper.pxi", line 1608, in pandas._libs.hashtable.PyObjectHashTable.get_item
KeyError: 'date'
[2020-06-28 19:42:05,157] {taskinstance.py:1168} INFO - Marking task as UP_FOR_RETRY
[2020-06-28 19:42:15,084] {logging_mixin.py:112} INFO - [2020-06-28 19:42:15,083] {local_task_job.py:103} INFO - Task exited with return code 1
[2020-06-28 19:51:53,048] {taskinstance.py:669} INFO - Dependencies all met for <TaskInstance: covid_stats.validate_and_clean_data 2020-06-27T00:00:00+00:00 [queued]>
[2020-06-28 19:51:53,064] {taskinstance.py:669} INFO - Dependencies all met for <TaskInstance: covid_stats.validate_and_clean_data 2020-06-27T00:00:00+00:00 [queued]>
[2020-06-28 19:51:53,064] {taskinstance.py:879} INFO - 
--------------------------------------------------------------------------------
[2020-06-28 19:51:53,065] {taskinstance.py:880} INFO - Starting attempt 2 of 6
[2020-06-28 19:51:53,065] {taskinstance.py:881} INFO - 
--------------------------------------------------------------------------------
[2020-06-28 19:51:53,073] {taskinstance.py:900} INFO - Executing <Task(PythonOperator): validate_and_clean_data> on 2020-06-27T00:00:00+00:00
[2020-06-28 19:51:53,076] {standard_task_runner.py:53} INFO - Started process 14333 to run task
[2020-06-28 19:51:53,127] {logging_mixin.py:112} INFO - Running %s on host %s <TaskInstance: covid_stats.validate_and_clean_data 2020-06-27T00:00:00+00:00 [running]> nineleaps-ThinkPad-E480
[2020-06-28 19:51:53,151] {taskinstance.py:1145} ERROR - 'date'
Traceback (most recent call last):
  File "/home/nineleaps/.local/lib/python2.7/site-packages/airflow/models/taskinstance.py", line 983, in _run_raw_task
    result = task_copy.execute(context=context)
  File "/home/nineleaps/.local/lib/python2.7/site-packages/airflow/operators/python_operator.py", line 113, in execute
    return_value = self.execute_callable()
  File "/home/nineleaps/.local/lib/python2.7/site-packages/airflow/operators/python_operator.py", line 118, in execute_callable
    return self.python_callable(*self.op_args, **self.op_kwargs)
  File "/home/nineleaps/airflow/plugins/validate_and_clean_data.py", line 30, in validate_and_clean_data
    pandas_df['date'] = pd.to_datetime(pandas_df['date'], format="%d-%m-%y").dt.date
  File "/home/nineleaps/.local/lib/python2.7/site-packages/pandas/core/frame.py", line 2927, in __getitem__
    indexer = self.columns.get_loc(key)
  File "/home/nineleaps/.local/lib/python2.7/site-packages/pandas/core/indexes/base.py", line 2659, in get_loc
    return self._engine.get_loc(self._maybe_cast_indexer(key))
  File "pandas/_libs/index.pyx", line 108, in pandas._libs.index.IndexEngine.get_loc
  File "pandas/_libs/index.pyx", line 132, in pandas._libs.index.IndexEngine.get_loc
  File "pandas/_libs/hashtable_class_helper.pxi", line 1601, in pandas._libs.hashtable.PyObjectHashTable.get_item
  File "pandas/_libs/hashtable_class_helper.pxi", line 1608, in pandas._libs.hashtable.PyObjectHashTable.get_item
KeyError: 'date'
[2020-06-28 19:51:53,156] {taskinstance.py:1168} INFO - Marking task as UP_FOR_RETRY
[2020-06-28 19:52:03,035] {logging_mixin.py:112} INFO - [2020-06-28 19:52:03,034] {local_task_job.py:103} INFO - Task exited with return code 1
[2020-06-28 20:03:27,642] {taskinstance.py:669} INFO - Dependencies all met for <TaskInstance: covid_stats.validate_and_clean_data 2020-06-27T00:00:00+00:00 [queued]>
[2020-06-28 20:03:27,651] {taskinstance.py:669} INFO - Dependencies all met for <TaskInstance: covid_stats.validate_and_clean_data 2020-06-27T00:00:00+00:00 [queued]>
[2020-06-28 20:03:27,651] {taskinstance.py:879} INFO - 
--------------------------------------------------------------------------------
[2020-06-28 20:03:27,651] {taskinstance.py:880} INFO - Starting attempt 2 of 6
[2020-06-28 20:03:27,651] {taskinstance.py:881} INFO - 
--------------------------------------------------------------------------------
[2020-06-28 20:03:27,657] {taskinstance.py:900} INFO - Executing <Task(PythonOperator): validate_and_clean_data> on 2020-06-27T00:00:00+00:00
[2020-06-28 20:03:27,659] {standard_task_runner.py:53} INFO - Started process 4722 to run task
[2020-06-28 20:03:27,706] {logging_mixin.py:112} INFO - Running %s on host %s <TaskInstance: covid_stats.validate_and_clean_data 2020-06-27T00:00:00+00:00 [running]> nineleaps-ThinkPad-E480
[2020-06-28 20:03:27,718] {taskinstance.py:1145} ERROR - 'date'
Traceback (most recent call last):
  File "/home/nineleaps/.local/lib/python2.7/site-packages/airflow/models/taskinstance.py", line 983, in _run_raw_task
    result = task_copy.execute(context=context)
  File "/home/nineleaps/.local/lib/python2.7/site-packages/airflow/operators/python_operator.py", line 113, in execute
    return_value = self.execute_callable()
  File "/home/nineleaps/.local/lib/python2.7/site-packages/airflow/operators/python_operator.py", line 118, in execute_callable
    return self.python_callable(*self.op_args, **self.op_kwargs)
  File "/home/nineleaps/airflow/plugins/validate_and_clean_data.py", line 30, in validate_and_clean_data
    pandas_df['date'] = pd.to_datetime(pandas_df['date'], format="%d-%m-%y").dt.date
  File "/home/nineleaps/.local/lib/python2.7/site-packages/pandas/core/frame.py", line 2927, in __getitem__
    indexer = self.columns.get_loc(key)
  File "/home/nineleaps/.local/lib/python2.7/site-packages/pandas/core/indexes/base.py", line 2659, in get_loc
    return self._engine.get_loc(self._maybe_cast_indexer(key))
  File "pandas/_libs/index.pyx", line 108, in pandas._libs.index.IndexEngine.get_loc
  File "pandas/_libs/index.pyx", line 132, in pandas._libs.index.IndexEngine.get_loc
  File "pandas/_libs/hashtable_class_helper.pxi", line 1601, in pandas._libs.hashtable.PyObjectHashTable.get_item
  File "pandas/_libs/hashtable_class_helper.pxi", line 1608, in pandas._libs.hashtable.PyObjectHashTable.get_item
KeyError: 'date'
[2020-06-28 20:03:27,721] {taskinstance.py:1168} INFO - Marking task as UP_FOR_RETRY
[2020-06-28 20:03:37,645] {logging_mixin.py:112} INFO - [2020-06-28 20:03:37,644] {local_task_job.py:103} INFO - Task exited with return code 1
[2020-06-28 20:11:38,691] {taskinstance.py:669} INFO - Dependencies all met for <TaskInstance: covid_stats.validate_and_clean_data 2020-06-27T00:00:00+00:00 [queued]>
[2020-06-28 20:11:38,700] {taskinstance.py:669} INFO - Dependencies all met for <TaskInstance: covid_stats.validate_and_clean_data 2020-06-27T00:00:00+00:00 [queued]>
[2020-06-28 20:11:38,700] {taskinstance.py:879} INFO - 
--------------------------------------------------------------------------------
[2020-06-28 20:11:38,700] {taskinstance.py:880} INFO - Starting attempt 2 of 6
[2020-06-28 20:11:38,700] {taskinstance.py:881} INFO - 
--------------------------------------------------------------------------------
[2020-06-28 20:11:38,707] {taskinstance.py:900} INFO - Executing <Task(PythonOperator): validate_and_clean_data> on 2020-06-27T00:00:00+00:00
[2020-06-28 20:11:38,708] {standard_task_runner.py:53} INFO - Started process 8969 to run task
[2020-06-28 20:11:38,750] {logging_mixin.py:112} INFO - Running %s on host %s <TaskInstance: covid_stats.validate_and_clean_data 2020-06-27T00:00:00+00:00 [running]> nineleaps-ThinkPad-E480
[2020-06-28 20:11:38,763] {taskinstance.py:1145} ERROR - 'date'
Traceback (most recent call last):
  File "/home/nineleaps/.local/lib/python2.7/site-packages/airflow/models/taskinstance.py", line 983, in _run_raw_task
    result = task_copy.execute(context=context)
  File "/home/nineleaps/.local/lib/python2.7/site-packages/airflow/operators/python_operator.py", line 113, in execute
    return_value = self.execute_callable()
  File "/home/nineleaps/.local/lib/python2.7/site-packages/airflow/operators/python_operator.py", line 118, in execute_callable
    return self.python_callable(*self.op_args, **self.op_kwargs)
  File "/home/nineleaps/airflow/plugins/validate_and_clean_data.py", line 30, in validate_and_clean_data
    pandas_df['date'] = pd.to_datetime(pandas_df['date'], format="%d-%m-%y").dt.date
  File "/home/nineleaps/.local/lib/python2.7/site-packages/pandas/core/frame.py", line 2927, in __getitem__
    indexer = self.columns.get_loc(key)
  File "/home/nineleaps/.local/lib/python2.7/site-packages/pandas/core/indexes/base.py", line 2659, in get_loc
    return self._engine.get_loc(self._maybe_cast_indexer(key))
  File "pandas/_libs/index.pyx", line 108, in pandas._libs.index.IndexEngine.get_loc
  File "pandas/_libs/index.pyx", line 132, in pandas._libs.index.IndexEngine.get_loc
  File "pandas/_libs/hashtable_class_helper.pxi", line 1601, in pandas._libs.hashtable.PyObjectHashTable.get_item
  File "pandas/_libs/hashtable_class_helper.pxi", line 1608, in pandas._libs.hashtable.PyObjectHashTable.get_item
KeyError: 'date'
[2020-06-28 20:11:38,766] {taskinstance.py:1168} INFO - Marking task as UP_FOR_RETRY
[2020-06-28 20:11:48,688] {logging_mixin.py:112} INFO - [2020-06-28 20:11:48,687] {local_task_job.py:103} INFO - Task exited with return code 1
[2020-06-28 20:26:19,883] {taskinstance.py:669} INFO - Dependencies all met for <TaskInstance: covid_stats.validate_and_clean_data 2020-06-27T00:00:00+00:00 [queued]>
[2020-06-28 20:26:19,893] {taskinstance.py:669} INFO - Dependencies all met for <TaskInstance: covid_stats.validate_and_clean_data 2020-06-27T00:00:00+00:00 [queued]>
[2020-06-28 20:26:19,893] {taskinstance.py:879} INFO - 
--------------------------------------------------------------------------------
[2020-06-28 20:26:19,893] {taskinstance.py:880} INFO - Starting attempt 2 of 6
[2020-06-28 20:26:19,893] {taskinstance.py:881} INFO - 
--------------------------------------------------------------------------------
[2020-06-28 20:26:19,901] {taskinstance.py:900} INFO - Executing <Task(PythonOperator): validate_and_clean_data> on 2020-06-27T00:00:00+00:00
[2020-06-28 20:26:19,903] {standard_task_runner.py:53} INFO - Started process 14979 to run task
[2020-06-28 20:26:19,940] {logging_mixin.py:112} INFO - Running %s on host %s <TaskInstance: covid_stats.validate_and_clean_data 2020-06-27T00:00:00+00:00 [running]> nineleaps-ThinkPad-E480
[2020-06-28 20:26:19,953] {taskinstance.py:1145} ERROR - 'date'
Traceback (most recent call last):
  File "/home/nineleaps/.local/lib/python2.7/site-packages/airflow/models/taskinstance.py", line 983, in _run_raw_task
    result = task_copy.execute(context=context)
  File "/home/nineleaps/.local/lib/python2.7/site-packages/airflow/operators/python_operator.py", line 113, in execute
    return_value = self.execute_callable()
  File "/home/nineleaps/.local/lib/python2.7/site-packages/airflow/operators/python_operator.py", line 118, in execute_callable
    return self.python_callable(*self.op_args, **self.op_kwargs)
  File "/home/nineleaps/airflow/plugins/validate_and_clean_data.py", line 30, in validate_and_clean_data
    pandas_df['date'] = pd.to_datetime(pandas_df['date'], format="%d-%b-%y").dt.date
  File "/home/nineleaps/.local/lib/python2.7/site-packages/pandas/core/frame.py", line 2927, in __getitem__
    indexer = self.columns.get_loc(key)
  File "/home/nineleaps/.local/lib/python2.7/site-packages/pandas/core/indexes/base.py", line 2659, in get_loc
    return self._engine.get_loc(self._maybe_cast_indexer(key))
  File "pandas/_libs/index.pyx", line 108, in pandas._libs.index.IndexEngine.get_loc
  File "pandas/_libs/index.pyx", line 132, in pandas._libs.index.IndexEngine.get_loc
  File "pandas/_libs/hashtable_class_helper.pxi", line 1601, in pandas._libs.hashtable.PyObjectHashTable.get_item
  File "pandas/_libs/hashtable_class_helper.pxi", line 1608, in pandas._libs.hashtable.PyObjectHashTable.get_item
KeyError: 'date'
[2020-06-28 20:26:19,956] {taskinstance.py:1168} INFO - Marking task as UP_FOR_RETRY
[2020-06-28 20:26:29,884] {logging_mixin.py:112} INFO - [2020-06-28 20:26:29,883] {local_task_job.py:103} INFO - Task exited with return code 1
[2020-06-29 11:23:51,184] {taskinstance.py:669} INFO - Dependencies all met for <TaskInstance: covid_stats.validate_and_clean_data 2020-06-27T00:00:00+00:00 [queued]>
[2020-06-29 11:23:51,194] {taskinstance.py:669} INFO - Dependencies all met for <TaskInstance: covid_stats.validate_and_clean_data 2020-06-27T00:00:00+00:00 [queued]>
[2020-06-29 11:23:51,194] {taskinstance.py:879} INFO - 
--------------------------------------------------------------------------------
[2020-06-29 11:23:51,194] {taskinstance.py:880} INFO - Starting attempt 2 of 6
[2020-06-29 11:23:51,194] {taskinstance.py:881} INFO - 
--------------------------------------------------------------------------------
[2020-06-29 11:23:51,201] {taskinstance.py:900} INFO - Executing <Task(PythonOperator): validate_and_clean_data> on 2020-06-27T00:00:00+00:00
[2020-06-29 11:23:51,203] {standard_task_runner.py:53} INFO - Started process 4676 to run task
[2020-06-29 11:23:51,238] {logging_mixin.py:112} INFO - Running %s on host %s <TaskInstance: covid_stats.validate_and_clean_data 2020-06-27T00:00:00+00:00 [running]> nineleaps-ThinkPad-E480
[2020-06-29 11:23:51,251] {taskinstance.py:1145} ERROR - 'date'
Traceback (most recent call last):
  File "/home/nineleaps/.local/lib/python2.7/site-packages/airflow/models/taskinstance.py", line 983, in _run_raw_task
    result = task_copy.execute(context=context)
  File "/home/nineleaps/.local/lib/python2.7/site-packages/airflow/operators/python_operator.py", line 113, in execute
    return_value = self.execute_callable()
  File "/home/nineleaps/.local/lib/python2.7/site-packages/airflow/operators/python_operator.py", line 118, in execute_callable
    return self.python_callable(*self.op_args, **self.op_kwargs)
  File "/home/nineleaps/airflow/plugins/validate_and_clean_data.py", line 30, in validate_and_clean_data
    pandas_df['date'] = pd.to_datetime(pandas_df['date'], format="%d-%b-%y").dt.date
  File "/home/nineleaps/.local/lib/python2.7/site-packages/pandas/core/frame.py", line 2927, in __getitem__
    indexer = self.columns.get_loc(key)
  File "/home/nineleaps/.local/lib/python2.7/site-packages/pandas/core/indexes/base.py", line 2659, in get_loc
    return self._engine.get_loc(self._maybe_cast_indexer(key))
  File "pandas/_libs/index.pyx", line 108, in pandas._libs.index.IndexEngine.get_loc
  File "pandas/_libs/index.pyx", line 132, in pandas._libs.index.IndexEngine.get_loc
  File "pandas/_libs/hashtable_class_helper.pxi", line 1601, in pandas._libs.hashtable.PyObjectHashTable.get_item
  File "pandas/_libs/hashtable_class_helper.pxi", line 1608, in pandas._libs.hashtable.PyObjectHashTable.get_item
KeyError: 'date'
[2020-06-29 11:23:51,254] {taskinstance.py:1168} INFO - Marking task as UP_FOR_RETRY
[2020-06-29 11:24:01,187] {logging_mixin.py:112} INFO - [2020-06-29 11:24:01,186] {local_task_job.py:103} INFO - Task exited with return code 1
