[2020-06-28 19:44:40,291] {taskinstance.py:669} INFO - Dependencies all met for <TaskInstance: covid_stats.validate_and_clean_data 2020-06-27T00:00:00+00:00 [queued]>
[2020-06-28 19:44:40,302] {taskinstance.py:669} INFO - Dependencies all met for <TaskInstance: covid_stats.validate_and_clean_data 2020-06-27T00:00:00+00:00 [queued]>
[2020-06-28 19:44:40,302] {taskinstance.py:879} INFO - 
--------------------------------------------------------------------------------
[2020-06-28 19:44:40,302] {taskinstance.py:880} INFO - Starting attempt 4 of 6
[2020-06-28 19:44:40,302] {taskinstance.py:881} INFO - 
--------------------------------------------------------------------------------
[2020-06-28 19:44:40,308] {taskinstance.py:900} INFO - Executing <Task(PythonOperator): validate_and_clean_data> on 2020-06-27T00:00:00+00:00
[2020-06-28 19:44:40,310] {standard_task_runner.py:53} INFO - Started process 11494 to run task
[2020-06-28 19:44:40,346] {logging_mixin.py:112} INFO - Running %s on host %s <TaskInstance: covid_stats.validate_and_clean_data 2020-06-27T00:00:00+00:00 [running]> nineleaps-ThinkPad-E480
[2020-06-28 19:44:40,359] {taskinstance.py:1145} ERROR - 'date'
Traceback (most recent call last):
  File "/home/nineleaps/.local/lib/python2.7/site-packages/airflow/models/taskinstance.py", line 983, in _run_raw_task
    result = task_copy.execute(context=context)
  File "/home/nineleaps/.local/lib/python2.7/site-packages/airflow/operators/python_operator.py", line 113, in execute
    return_value = self.execute_callable()
  File "/home/nineleaps/.local/lib/python2.7/site-packages/airflow/operators/python_operator.py", line 118, in execute_callable
    return self.python_callable(*self.op_args, **self.op_kwargs)
  File "/home/nineleaps/airflow/plugins/validate_and_clean_data.py", line 30, in validate_and_clean_data
    pandas_df['date'] = pd.to_datetime(pandas_df['date'], format="%d-%b-%y").dt.date
  File "/home/nineleaps/.local/lib/python2.7/site-packages/pandas/core/frame.py", line 2927, in __getitem__
    indexer = self.columns.get_loc(key)
  File "/home/nineleaps/.local/lib/python2.7/site-packages/pandas/core/indexes/base.py", line 2659, in get_loc
    return self._engine.get_loc(self._maybe_cast_indexer(key))
  File "pandas/_libs/index.pyx", line 108, in pandas._libs.index.IndexEngine.get_loc
  File "pandas/_libs/index.pyx", line 132, in pandas._libs.index.IndexEngine.get_loc
  File "pandas/_libs/hashtable_class_helper.pxi", line 1601, in pandas._libs.hashtable.PyObjectHashTable.get_item
  File "pandas/_libs/hashtable_class_helper.pxi", line 1608, in pandas._libs.hashtable.PyObjectHashTable.get_item
KeyError: 'date'
[2020-06-28 19:44:40,362] {taskinstance.py:1168} INFO - Marking task as UP_FOR_RETRY
[2020-06-28 19:44:50,290] {logging_mixin.py:112} INFO - [2020-06-28 19:44:50,289] {local_task_job.py:103} INFO - Task exited with return code 1
[2020-06-28 20:06:03,159] {taskinstance.py:669} INFO - Dependencies all met for <TaskInstance: covid_stats.validate_and_clean_data 2020-06-27T00:00:00+00:00 [queued]>
[2020-06-28 20:06:03,169] {taskinstance.py:669} INFO - Dependencies all met for <TaskInstance: covid_stats.validate_and_clean_data 2020-06-27T00:00:00+00:00 [queued]>
[2020-06-28 20:06:03,169] {taskinstance.py:879} INFO - 
--------------------------------------------------------------------------------
[2020-06-28 20:06:03,169] {taskinstance.py:880} INFO - Starting attempt 4 of 6
[2020-06-28 20:06:03,169] {taskinstance.py:881} INFO - 
--------------------------------------------------------------------------------
[2020-06-28 20:06:03,176] {taskinstance.py:900} INFO - Executing <Task(PythonOperator): validate_and_clean_data> on 2020-06-27T00:00:00+00:00
[2020-06-28 20:06:03,178] {standard_task_runner.py:53} INFO - Started process 5884 to run task
[2020-06-28 20:06:03,213] {logging_mixin.py:112} INFO - Running %s on host %s <TaskInstance: covid_stats.validate_and_clean_data 2020-06-27T00:00:00+00:00 [running]> nineleaps-ThinkPad-E480
[2020-06-28 20:06:03,226] {taskinstance.py:1145} ERROR - 'date'
Traceback (most recent call last):
  File "/home/nineleaps/.local/lib/python2.7/site-packages/airflow/models/taskinstance.py", line 983, in _run_raw_task
    result = task_copy.execute(context=context)
  File "/home/nineleaps/.local/lib/python2.7/site-packages/airflow/operators/python_operator.py", line 113, in execute
    return_value = self.execute_callable()
  File "/home/nineleaps/.local/lib/python2.7/site-packages/airflow/operators/python_operator.py", line 118, in execute_callable
    return self.python_callable(*self.op_args, **self.op_kwargs)
  File "/home/nineleaps/airflow/plugins/validate_and_clean_data.py", line 30, in validate_and_clean_data
    pandas_df['date'] = pd.to_datetime(pandas_df['date'], format="%d-%m-%y").dt.date
  File "/home/nineleaps/.local/lib/python2.7/site-packages/pandas/core/frame.py", line 2927, in __getitem__
    indexer = self.columns.get_loc(key)
  File "/home/nineleaps/.local/lib/python2.7/site-packages/pandas/core/indexes/base.py", line 2659, in get_loc
    return self._engine.get_loc(self._maybe_cast_indexer(key))
  File "pandas/_libs/index.pyx", line 108, in pandas._libs.index.IndexEngine.get_loc
  File "pandas/_libs/index.pyx", line 132, in pandas._libs.index.IndexEngine.get_loc
  File "pandas/_libs/hashtable_class_helper.pxi", line 1601, in pandas._libs.hashtable.PyObjectHashTable.get_item
  File "pandas/_libs/hashtable_class_helper.pxi", line 1608, in pandas._libs.hashtable.PyObjectHashTable.get_item
KeyError: 'date'
[2020-06-28 20:06:03,229] {taskinstance.py:1168} INFO - Marking task as UP_FOR_RETRY
[2020-06-28 20:06:13,160] {logging_mixin.py:112} INFO - [2020-06-28 20:06:13,159] {local_task_job.py:103} INFO - Task exited with return code 1
[2020-06-28 20:14:14,758] {taskinstance.py:669} INFO - Dependencies all met for <TaskInstance: covid_stats.validate_and_clean_data 2020-06-27T00:00:00+00:00 [queued]>
[2020-06-28 20:14:14,767] {taskinstance.py:669} INFO - Dependencies all met for <TaskInstance: covid_stats.validate_and_clean_data 2020-06-27T00:00:00+00:00 [queued]>
[2020-06-28 20:14:14,767] {taskinstance.py:879} INFO - 
--------------------------------------------------------------------------------
[2020-06-28 20:14:14,767] {taskinstance.py:880} INFO - Starting attempt 4 of 6
[2020-06-28 20:14:14,767] {taskinstance.py:881} INFO - 
--------------------------------------------------------------------------------
[2020-06-28 20:14:14,774] {taskinstance.py:900} INFO - Executing <Task(PythonOperator): validate_and_clean_data> on 2020-06-27T00:00:00+00:00
[2020-06-28 20:14:14,776] {standard_task_runner.py:53} INFO - Started process 10561 to run task
[2020-06-28 20:14:14,825] {logging_mixin.py:112} INFO - Running %s on host %s <TaskInstance: covid_stats.validate_and_clean_data 2020-06-27T00:00:00+00:00 [running]> nineleaps-ThinkPad-E480
[2020-06-28 20:14:14,839] {taskinstance.py:1145} ERROR - 'date'
Traceback (most recent call last):
  File "/home/nineleaps/.local/lib/python2.7/site-packages/airflow/models/taskinstance.py", line 983, in _run_raw_task
    result = task_copy.execute(context=context)
  File "/home/nineleaps/.local/lib/python2.7/site-packages/airflow/operators/python_operator.py", line 113, in execute
    return_value = self.execute_callable()
  File "/home/nineleaps/.local/lib/python2.7/site-packages/airflow/operators/python_operator.py", line 118, in execute_callable
    return self.python_callable(*self.op_args, **self.op_kwargs)
  File "/home/nineleaps/airflow/plugins/validate_and_clean_data.py", line 30, in validate_and_clean_data
    pandas_df['date'] = pd.to_datetime(pandas_df['date'], format="%d-%m-%y").dt.date
  File "/home/nineleaps/.local/lib/python2.7/site-packages/pandas/core/frame.py", line 2927, in __getitem__
    indexer = self.columns.get_loc(key)
  File "/home/nineleaps/.local/lib/python2.7/site-packages/pandas/core/indexes/base.py", line 2659, in get_loc
    return self._engine.get_loc(self._maybe_cast_indexer(key))
  File "pandas/_libs/index.pyx", line 108, in pandas._libs.index.IndexEngine.get_loc
  File "pandas/_libs/index.pyx", line 132, in pandas._libs.index.IndexEngine.get_loc
  File "pandas/_libs/hashtable_class_helper.pxi", line 1601, in pandas._libs.hashtable.PyObjectHashTable.get_item
  File "pandas/_libs/hashtable_class_helper.pxi", line 1608, in pandas._libs.hashtable.PyObjectHashTable.get_item
KeyError: 'date'
[2020-06-28 20:14:14,841] {taskinstance.py:1168} INFO - Marking task as UP_FOR_RETRY
[2020-06-28 20:14:24,747] {logging_mixin.py:112} INFO - [2020-06-28 20:14:24,747] {local_task_job.py:103} INFO - Task exited with return code 1
[2020-06-28 20:28:57,874] {taskinstance.py:669} INFO - Dependencies all met for <TaskInstance: covid_stats.validate_and_clean_data 2020-06-27T00:00:00+00:00 [queued]>
[2020-06-28 20:28:57,887] {taskinstance.py:669} INFO - Dependencies all met for <TaskInstance: covid_stats.validate_and_clean_data 2020-06-27T00:00:00+00:00 [queued]>
[2020-06-28 20:28:57,887] {taskinstance.py:879} INFO - 
--------------------------------------------------------------------------------
[2020-06-28 20:28:57,887] {taskinstance.py:880} INFO - Starting attempt 4 of 6
[2020-06-28 20:28:57,887] {taskinstance.py:881} INFO - 
--------------------------------------------------------------------------------
[2020-06-28 20:28:57,896] {taskinstance.py:900} INFO - Executing <Task(PythonOperator): validate_and_clean_data> on 2020-06-27T00:00:00+00:00
[2020-06-28 20:28:57,898] {standard_task_runner.py:53} INFO - Started process 16042 to run task
[2020-06-28 20:28:57,950] {logging_mixin.py:112} INFO - Running %s on host %s <TaskInstance: covid_stats.validate_and_clean_data 2020-06-27T00:00:00+00:00 [running]> nineleaps-ThinkPad-E480
[2020-06-28 20:28:57,968] {taskinstance.py:1145} ERROR - 'date'
Traceback (most recent call last):
  File "/home/nineleaps/.local/lib/python2.7/site-packages/airflow/models/taskinstance.py", line 983, in _run_raw_task
    result = task_copy.execute(context=context)
  File "/home/nineleaps/.local/lib/python2.7/site-packages/airflow/operators/python_operator.py", line 113, in execute
    return_value = self.execute_callable()
  File "/home/nineleaps/.local/lib/python2.7/site-packages/airflow/operators/python_operator.py", line 118, in execute_callable
    return self.python_callable(*self.op_args, **self.op_kwargs)
  File "/home/nineleaps/airflow/plugins/validate_and_clean_data.py", line 30, in validate_and_clean_data
    pandas_df['date'] = pd.to_datetime(pandas_df['date'], format="%d-%b-%y").dt.date
  File "/home/nineleaps/.local/lib/python2.7/site-packages/pandas/core/frame.py", line 2927, in __getitem__
    indexer = self.columns.get_loc(key)
  File "/home/nineleaps/.local/lib/python2.7/site-packages/pandas/core/indexes/base.py", line 2659, in get_loc
    return self._engine.get_loc(self._maybe_cast_indexer(key))
  File "pandas/_libs/index.pyx", line 108, in pandas._libs.index.IndexEngine.get_loc
  File "pandas/_libs/index.pyx", line 132, in pandas._libs.index.IndexEngine.get_loc
  File "pandas/_libs/hashtable_class_helper.pxi", line 1601, in pandas._libs.hashtable.PyObjectHashTable.get_item
  File "pandas/_libs/hashtable_class_helper.pxi", line 1608, in pandas._libs.hashtable.PyObjectHashTable.get_item
KeyError: 'date'
[2020-06-28 20:28:57,972] {taskinstance.py:1168} INFO - Marking task as UP_FOR_RETRY
[2020-06-28 20:29:07,871] {logging_mixin.py:112} INFO - [2020-06-28 20:29:07,870] {local_task_job.py:103} INFO - Task exited with return code 1
[2020-06-29 11:27:24,141] {taskinstance.py:669} INFO - Dependencies all met for <TaskInstance: covid_stats.validate_and_clean_data 2020-06-27T00:00:00+00:00 [queued]>
[2020-06-29 11:27:24,148] {taskinstance.py:669} INFO - Dependencies all met for <TaskInstance: covid_stats.validate_and_clean_data 2020-06-27T00:00:00+00:00 [queued]>
[2020-06-29 11:27:24,148] {taskinstance.py:879} INFO - 
--------------------------------------------------------------------------------
[2020-06-29 11:27:24,148] {taskinstance.py:880} INFO - Starting attempt 4 of 6
[2020-06-29 11:27:24,149] {taskinstance.py:881} INFO - 
--------------------------------------------------------------------------------
[2020-06-29 11:27:24,155] {taskinstance.py:900} INFO - Executing <Task(PythonOperator): validate_and_clean_data> on 2020-06-27T00:00:00+00:00
[2020-06-29 11:27:24,157] {standard_task_runner.py:53} INFO - Started process 6687 to run task
[2020-06-29 11:27:24,194] {logging_mixin.py:112} INFO - Running %s on host %s <TaskInstance: covid_stats.validate_and_clean_data 2020-06-27T00:00:00+00:00 [running]> nineleaps-ThinkPad-E480
[2020-06-29 11:27:24,207] {taskinstance.py:1145} ERROR - 'date'
Traceback (most recent call last):
  File "/home/nineleaps/.local/lib/python2.7/site-packages/airflow/models/taskinstance.py", line 983, in _run_raw_task
    result = task_copy.execute(context=context)
  File "/home/nineleaps/.local/lib/python2.7/site-packages/airflow/operators/python_operator.py", line 113, in execute
    return_value = self.execute_callable()
  File "/home/nineleaps/.local/lib/python2.7/site-packages/airflow/operators/python_operator.py", line 118, in execute_callable
    return self.python_callable(*self.op_args, **self.op_kwargs)
  File "/home/nineleaps/airflow/plugins/validate_and_clean_data.py", line 30, in validate_and_clean_data
    pandas_df['date'] = pd.to_datetime(pandas_df['date'], format="%d-%b-%y").dt.date
  File "/home/nineleaps/.local/lib/python2.7/site-packages/pandas/core/frame.py", line 2927, in __getitem__
    indexer = self.columns.get_loc(key)
  File "/home/nineleaps/.local/lib/python2.7/site-packages/pandas/core/indexes/base.py", line 2659, in get_loc
    return self._engine.get_loc(self._maybe_cast_indexer(key))
  File "pandas/_libs/index.pyx", line 108, in pandas._libs.index.IndexEngine.get_loc
  File "pandas/_libs/index.pyx", line 132, in pandas._libs.index.IndexEngine.get_loc
  File "pandas/_libs/hashtable_class_helper.pxi", line 1601, in pandas._libs.hashtable.PyObjectHashTable.get_item
  File "pandas/_libs/hashtable_class_helper.pxi", line 1608, in pandas._libs.hashtable.PyObjectHashTable.get_item
KeyError: 'date'
[2020-06-29 11:27:24,212] {taskinstance.py:1168} INFO - Marking task as UP_FOR_RETRY
[2020-06-29 11:27:34,135] {logging_mixin.py:112} INFO - [2020-06-29 11:27:34,135] {local_task_job.py:103} INFO - Task exited with return code 1
