[2020-06-28 19:45:58,351] {taskinstance.py:669} INFO - Dependencies all met for <TaskInstance: covid_stats.validate_and_clean_data 2020-06-27T00:00:00+00:00 [queued]>
[2020-06-28 19:45:58,360] {taskinstance.py:669} INFO - Dependencies all met for <TaskInstance: covid_stats.validate_and_clean_data 2020-06-27T00:00:00+00:00 [queued]>
[2020-06-28 19:45:58,360] {taskinstance.py:879} INFO - 
--------------------------------------------------------------------------------
[2020-06-28 19:45:58,360] {taskinstance.py:880} INFO - Starting attempt 5 of 6
[2020-06-28 19:45:58,360] {taskinstance.py:881} INFO - 
--------------------------------------------------------------------------------
[2020-06-28 19:45:58,368] {taskinstance.py:900} INFO - Executing <Task(PythonOperator): validate_and_clean_data> on 2020-06-27T00:00:00+00:00
[2020-06-28 19:45:58,370] {standard_task_runner.py:53} INFO - Started process 12237 to run task
[2020-06-28 19:45:58,406] {logging_mixin.py:112} INFO - Running %s on host %s <TaskInstance: covid_stats.validate_and_clean_data 2020-06-27T00:00:00+00:00 [running]> nineleaps-ThinkPad-E480
[2020-06-28 19:45:58,419] {taskinstance.py:1145} ERROR - 'date'
Traceback (most recent call last):
  File "/home/nineleaps/.local/lib/python2.7/site-packages/airflow/models/taskinstance.py", line 983, in _run_raw_task
    result = task_copy.execute(context=context)
  File "/home/nineleaps/.local/lib/python2.7/site-packages/airflow/operators/python_operator.py", line 113, in execute
    return_value = self.execute_callable()
  File "/home/nineleaps/.local/lib/python2.7/site-packages/airflow/operators/python_operator.py", line 118, in execute_callable
    return self.python_callable(*self.op_args, **self.op_kwargs)
  File "/home/nineleaps/airflow/plugins/validate_and_clean_data.py", line 30, in validate_and_clean_data
    pandas_df['date'] = pd.to_datetime(pandas_df['date'], format="%d-%b-%y").dt.date
  File "/home/nineleaps/.local/lib/python2.7/site-packages/pandas/core/frame.py", line 2927, in __getitem__
    indexer = self.columns.get_loc(key)
  File "/home/nineleaps/.local/lib/python2.7/site-packages/pandas/core/indexes/base.py", line 2659, in get_loc
    return self._engine.get_loc(self._maybe_cast_indexer(key))
  File "pandas/_libs/index.pyx", line 108, in pandas._libs.index.IndexEngine.get_loc
  File "pandas/_libs/index.pyx", line 132, in pandas._libs.index.IndexEngine.get_loc
  File "pandas/_libs/hashtable_class_helper.pxi", line 1601, in pandas._libs.hashtable.PyObjectHashTable.get_item
  File "pandas/_libs/hashtable_class_helper.pxi", line 1608, in pandas._libs.hashtable.PyObjectHashTable.get_item
KeyError: 'date'
[2020-06-28 19:45:58,422] {taskinstance.py:1168} INFO - Marking task as UP_FOR_RETRY
[2020-06-28 19:46:08,347] {logging_mixin.py:112} INFO - [2020-06-28 19:46:08,346] {local_task_job.py:103} INFO - Task exited with return code 1
[2020-06-28 20:15:32,098] {taskinstance.py:669} INFO - Dependencies all met for <TaskInstance: covid_stats.validate_and_clean_data 2020-06-27T00:00:00+00:00 [queued]>
[2020-06-28 20:15:32,108] {taskinstance.py:669} INFO - Dependencies all met for <TaskInstance: covid_stats.validate_and_clean_data 2020-06-27T00:00:00+00:00 [queued]>
[2020-06-28 20:15:32,108] {taskinstance.py:879} INFO - 
--------------------------------------------------------------------------------
[2020-06-28 20:15:32,108] {taskinstance.py:880} INFO - Starting attempt 5 of 6
[2020-06-28 20:15:32,108] {taskinstance.py:881} INFO - 
--------------------------------------------------------------------------------
[2020-06-28 20:15:32,115] {taskinstance.py:900} INFO - Executing <Task(PythonOperator): validate_and_clean_data> on 2020-06-27T00:00:00+00:00
[2020-06-28 20:15:32,117] {standard_task_runner.py:53} INFO - Started process 10973 to run task
[2020-06-28 20:15:32,153] {logging_mixin.py:112} INFO - Running %s on host %s <TaskInstance: covid_stats.validate_and_clean_data 2020-06-27T00:00:00+00:00 [running]> nineleaps-ThinkPad-E480
[2020-06-28 20:15:32,166] {taskinstance.py:1145} ERROR - 'date'
Traceback (most recent call last):
  File "/home/nineleaps/.local/lib/python2.7/site-packages/airflow/models/taskinstance.py", line 983, in _run_raw_task
    result = task_copy.execute(context=context)
  File "/home/nineleaps/.local/lib/python2.7/site-packages/airflow/operators/python_operator.py", line 113, in execute
    return_value = self.execute_callable()
  File "/home/nineleaps/.local/lib/python2.7/site-packages/airflow/operators/python_operator.py", line 118, in execute_callable
    return self.python_callable(*self.op_args, **self.op_kwargs)
  File "/home/nineleaps/airflow/plugins/validate_and_clean_data.py", line 30, in validate_and_clean_data
    pandas_df['date'] = pd.to_datetime(pandas_df['date'], format="%d-%m-%y").dt.date
  File "/home/nineleaps/.local/lib/python2.7/site-packages/pandas/core/frame.py", line 2927, in __getitem__
    indexer = self.columns.get_loc(key)
  File "/home/nineleaps/.local/lib/python2.7/site-packages/pandas/core/indexes/base.py", line 2659, in get_loc
    return self._engine.get_loc(self._maybe_cast_indexer(key))
  File "pandas/_libs/index.pyx", line 108, in pandas._libs.index.IndexEngine.get_loc
  File "pandas/_libs/index.pyx", line 132, in pandas._libs.index.IndexEngine.get_loc
  File "pandas/_libs/hashtable_class_helper.pxi", line 1601, in pandas._libs.hashtable.PyObjectHashTable.get_item
  File "pandas/_libs/hashtable_class_helper.pxi", line 1608, in pandas._libs.hashtable.PyObjectHashTable.get_item
KeyError: 'date'
[2020-06-28 20:15:32,170] {taskinstance.py:1168} INFO - Marking task as UP_FOR_RETRY
[2020-06-28 20:15:42,092] {logging_mixin.py:112} INFO - [2020-06-28 20:15:42,091] {local_task_job.py:103} INFO - Task exited with return code 1
[2020-06-28 20:30:16,442] {taskinstance.py:669} INFO - Dependencies all met for <TaskInstance: covid_stats.validate_and_clean_data 2020-06-27T00:00:00+00:00 [queued]>
[2020-06-28 20:30:16,452] {taskinstance.py:669} INFO - Dependencies all met for <TaskInstance: covid_stats.validate_and_clean_data 2020-06-27T00:00:00+00:00 [queued]>
[2020-06-28 20:30:16,452] {taskinstance.py:879} INFO - 
--------------------------------------------------------------------------------
[2020-06-28 20:30:16,452] {taskinstance.py:880} INFO - Starting attempt 5 of 6
[2020-06-28 20:30:16,452] {taskinstance.py:881} INFO - 
--------------------------------------------------------------------------------
[2020-06-28 20:30:16,461] {taskinstance.py:900} INFO - Executing <Task(PythonOperator): validate_and_clean_data> on 2020-06-27T00:00:00+00:00
[2020-06-28 20:30:16,463] {standard_task_runner.py:53} INFO - Started process 16565 to run task
[2020-06-28 20:30:16,506] {logging_mixin.py:112} INFO - Running %s on host %s <TaskInstance: covid_stats.validate_and_clean_data 2020-06-27T00:00:00+00:00 [running]> nineleaps-ThinkPad-E480
[2020-06-28 20:30:16,520] {taskinstance.py:1145} ERROR - 'date'
Traceback (most recent call last):
  File "/home/nineleaps/.local/lib/python2.7/site-packages/airflow/models/taskinstance.py", line 983, in _run_raw_task
    result = task_copy.execute(context=context)
  File "/home/nineleaps/.local/lib/python2.7/site-packages/airflow/operators/python_operator.py", line 113, in execute
    return_value = self.execute_callable()
  File "/home/nineleaps/.local/lib/python2.7/site-packages/airflow/operators/python_operator.py", line 118, in execute_callable
    return self.python_callable(*self.op_args, **self.op_kwargs)
  File "/home/nineleaps/airflow/plugins/validate_and_clean_data.py", line 30, in validate_and_clean_data
    pandas_df['date'] = pd.to_datetime(pandas_df['date'], format="%d-%b-%y").dt.date
  File "/home/nineleaps/.local/lib/python2.7/site-packages/pandas/core/frame.py", line 2927, in __getitem__
    indexer = self.columns.get_loc(key)
  File "/home/nineleaps/.local/lib/python2.7/site-packages/pandas/core/indexes/base.py", line 2659, in get_loc
    return self._engine.get_loc(self._maybe_cast_indexer(key))
  File "pandas/_libs/index.pyx", line 108, in pandas._libs.index.IndexEngine.get_loc
  File "pandas/_libs/index.pyx", line 132, in pandas._libs.index.IndexEngine.get_loc
  File "pandas/_libs/hashtable_class_helper.pxi", line 1601, in pandas._libs.hashtable.PyObjectHashTable.get_item
  File "pandas/_libs/hashtable_class_helper.pxi", line 1608, in pandas._libs.hashtable.PyObjectHashTable.get_item
KeyError: 'date'
[2020-06-28 20:30:16,523] {taskinstance.py:1168} INFO - Marking task as UP_FOR_RETRY
[2020-06-28 20:30:26,442] {logging_mixin.py:112} INFO - [2020-06-28 20:30:26,441] {local_task_job.py:103} INFO - Task exited with return code 1
[2020-06-29 11:28:57,291] {taskinstance.py:669} INFO - Dependencies all met for <TaskInstance: covid_stats.validate_and_clean_data 2020-06-27T00:00:00+00:00 [queued]>
[2020-06-29 11:28:57,301] {taskinstance.py:669} INFO - Dependencies all met for <TaskInstance: covid_stats.validate_and_clean_data 2020-06-27T00:00:00+00:00 [queued]>
[2020-06-29 11:28:57,301] {taskinstance.py:879} INFO - 
--------------------------------------------------------------------------------
[2020-06-29 11:28:57,301] {taskinstance.py:880} INFO - Starting attempt 5 of 6
[2020-06-29 11:28:57,302] {taskinstance.py:881} INFO - 
--------------------------------------------------------------------------------
[2020-06-29 11:28:57,311] {taskinstance.py:900} INFO - Executing <Task(PythonOperator): validate_and_clean_data> on 2020-06-27T00:00:00+00:00
[2020-06-29 11:28:57,313] {standard_task_runner.py:53} INFO - Started process 7496 to run task
[2020-06-29 11:28:57,361] {logging_mixin.py:112} INFO - Running %s on host %s <TaskInstance: covid_stats.validate_and_clean_data 2020-06-27T00:00:00+00:00 [running]> nineleaps-ThinkPad-E480
[2020-06-29 11:28:57,379] {taskinstance.py:1145} ERROR - 'date'
Traceback (most recent call last):
  File "/home/nineleaps/.local/lib/python2.7/site-packages/airflow/models/taskinstance.py", line 983, in _run_raw_task
    result = task_copy.execute(context=context)
  File "/home/nineleaps/.local/lib/python2.7/site-packages/airflow/operators/python_operator.py", line 113, in execute
    return_value = self.execute_callable()
  File "/home/nineleaps/.local/lib/python2.7/site-packages/airflow/operators/python_operator.py", line 118, in execute_callable
    return self.python_callable(*self.op_args, **self.op_kwargs)
  File "/home/nineleaps/airflow/plugins/validate_and_clean_data.py", line 30, in validate_and_clean_data
    pandas_df['date'] = pd.to_datetime(pandas_df['date'], format="%d-%b-%y").dt.date
  File "/home/nineleaps/.local/lib/python2.7/site-packages/pandas/core/frame.py", line 2927, in __getitem__
    indexer = self.columns.get_loc(key)
  File "/home/nineleaps/.local/lib/python2.7/site-packages/pandas/core/indexes/base.py", line 2659, in get_loc
    return self._engine.get_loc(self._maybe_cast_indexer(key))
  File "pandas/_libs/index.pyx", line 108, in pandas._libs.index.IndexEngine.get_loc
  File "pandas/_libs/index.pyx", line 132, in pandas._libs.index.IndexEngine.get_loc
  File "pandas/_libs/hashtable_class_helper.pxi", line 1601, in pandas._libs.hashtable.PyObjectHashTable.get_item
  File "pandas/_libs/hashtable_class_helper.pxi", line 1608, in pandas._libs.hashtable.PyObjectHashTable.get_item
KeyError: 'date'
[2020-06-29 11:28:57,382] {taskinstance.py:1168} INFO - Marking task as UP_FOR_RETRY
[2020-06-29 11:29:07,291] {logging_mixin.py:112} INFO - [2020-06-29 11:29:07,290] {local_task_job.py:103} INFO - Task exited with return code 1
