[2020-06-28 19:47:19,117] {taskinstance.py:669} INFO - Dependencies all met for <TaskInstance: covid_stats.validate_and_clean_data 2020-06-27T00:00:00+00:00 [queued]>
[2020-06-28 19:47:19,131] {taskinstance.py:669} INFO - Dependencies all met for <TaskInstance: covid_stats.validate_and_clean_data 2020-06-27T00:00:00+00:00 [queued]>
[2020-06-28 19:47:19,131] {taskinstance.py:879} INFO - 
--------------------------------------------------------------------------------
[2020-06-28 19:47:19,131] {taskinstance.py:880} INFO - Starting attempt 6 of 6
[2020-06-28 19:47:19,131] {taskinstance.py:881} INFO - 
--------------------------------------------------------------------------------
[2020-06-28 19:47:19,138] {taskinstance.py:900} INFO - Executing <Task(PythonOperator): validate_and_clean_data> on 2020-06-27T00:00:00+00:00
[2020-06-28 19:47:19,141] {standard_task_runner.py:53} INFO - Started process 12729 to run task
[2020-06-28 19:47:19,186] {logging_mixin.py:112} INFO - Running %s on host %s <TaskInstance: covid_stats.validate_and_clean_data 2020-06-27T00:00:00+00:00 [running]> nineleaps-ThinkPad-E480
[2020-06-28 19:47:19,206] {taskinstance.py:1145} ERROR - 'date'
Traceback (most recent call last):
  File "/home/nineleaps/.local/lib/python2.7/site-packages/airflow/models/taskinstance.py", line 983, in _run_raw_task
    result = task_copy.execute(context=context)
  File "/home/nineleaps/.local/lib/python2.7/site-packages/airflow/operators/python_operator.py", line 113, in execute
    return_value = self.execute_callable()
  File "/home/nineleaps/.local/lib/python2.7/site-packages/airflow/operators/python_operator.py", line 118, in execute_callable
    return self.python_callable(*self.op_args, **self.op_kwargs)
  File "/home/nineleaps/airflow/plugins/validate_and_clean_data.py", line 30, in validate_and_clean_data
    pandas_df['date'] = pd.to_datetime(pandas_df['date'], format="%d-%b-%y").dt.date
  File "/home/nineleaps/.local/lib/python2.7/site-packages/pandas/core/frame.py", line 2927, in __getitem__
    indexer = self.columns.get_loc(key)
  File "/home/nineleaps/.local/lib/python2.7/site-packages/pandas/core/indexes/base.py", line 2659, in get_loc
    return self._engine.get_loc(self._maybe_cast_indexer(key))
  File "pandas/_libs/index.pyx", line 108, in pandas._libs.index.IndexEngine.get_loc
  File "pandas/_libs/index.pyx", line 132, in pandas._libs.index.IndexEngine.get_loc
  File "pandas/_libs/hashtable_class_helper.pxi", line 1601, in pandas._libs.hashtable.PyObjectHashTable.get_item
  File "pandas/_libs/hashtable_class_helper.pxi", line 1608, in pandas._libs.hashtable.PyObjectHashTable.get_item
KeyError: 'date'
[2020-06-28 19:47:19,210] {taskinstance.py:1187} INFO - All retries failed; marking task as FAILED.dag_id=covid_stats, task_id=validate_and_clean_data, execution_date=20200627T000000, start_date=20200628T141719, end_date=20200628T141719
[2020-06-28 19:47:29,109] {logging_mixin.py:112} INFO - [2020-06-28 19:47:29,108] {local_task_job.py:103} INFO - Task exited with return code 1
[2020-06-28 20:16:51,681] {taskinstance.py:669} INFO - Dependencies all met for <TaskInstance: covid_stats.validate_and_clean_data 2020-06-27T00:00:00+00:00 [queued]>
[2020-06-28 20:16:51,694] {taskinstance.py:669} INFO - Dependencies all met for <TaskInstance: covid_stats.validate_and_clean_data 2020-06-27T00:00:00+00:00 [queued]>
[2020-06-28 20:16:51,694] {taskinstance.py:879} INFO - 
--------------------------------------------------------------------------------
[2020-06-28 20:16:51,695] {taskinstance.py:880} INFO - Starting attempt 6 of 6
[2020-06-28 20:16:51,695] {taskinstance.py:881} INFO - 
--------------------------------------------------------------------------------
[2020-06-28 20:16:51,704] {taskinstance.py:900} INFO - Executing <Task(PythonOperator): validate_and_clean_data> on 2020-06-27T00:00:00+00:00
[2020-06-28 20:16:51,706] {standard_task_runner.py:53} INFO - Started process 11782 to run task
[2020-06-28 20:16:51,752] {logging_mixin.py:112} INFO - Running %s on host %s <TaskInstance: covid_stats.validate_and_clean_data 2020-06-27T00:00:00+00:00 [running]> nineleaps-ThinkPad-E480
[2020-06-28 20:16:51,769] {taskinstance.py:1145} ERROR - 'date'
Traceback (most recent call last):
  File "/home/nineleaps/.local/lib/python2.7/site-packages/airflow/models/taskinstance.py", line 983, in _run_raw_task
    result = task_copy.execute(context=context)
  File "/home/nineleaps/.local/lib/python2.7/site-packages/airflow/operators/python_operator.py", line 113, in execute
    return_value = self.execute_callable()
  File "/home/nineleaps/.local/lib/python2.7/site-packages/airflow/operators/python_operator.py", line 118, in execute_callable
    return self.python_callable(*self.op_args, **self.op_kwargs)
  File "/home/nineleaps/airflow/plugins/validate_and_clean_data.py", line 30, in validate_and_clean_data
    pandas_df['date'] = pd.to_datetime(pandas_df['date'], format="%d-%m-%y").dt.date
  File "/home/nineleaps/.local/lib/python2.7/site-packages/pandas/core/frame.py", line 2927, in __getitem__
    indexer = self.columns.get_loc(key)
  File "/home/nineleaps/.local/lib/python2.7/site-packages/pandas/core/indexes/base.py", line 2659, in get_loc
    return self._engine.get_loc(self._maybe_cast_indexer(key))
  File "pandas/_libs/index.pyx", line 108, in pandas._libs.index.IndexEngine.get_loc
  File "pandas/_libs/index.pyx", line 132, in pandas._libs.index.IndexEngine.get_loc
  File "pandas/_libs/hashtable_class_helper.pxi", line 1601, in pandas._libs.hashtable.PyObjectHashTable.get_item
  File "pandas/_libs/hashtable_class_helper.pxi", line 1608, in pandas._libs.hashtable.PyObjectHashTable.get_item
KeyError: 'date'
[2020-06-28 20:16:51,772] {taskinstance.py:1187} INFO - All retries failed; marking task as FAILED.dag_id=covid_stats, task_id=validate_and_clean_data, execution_date=20200627T000000, start_date=20200628T144651, end_date=20200628T144651
[2020-06-28 20:17:01,673] {logging_mixin.py:112} INFO - [2020-06-28 20:17:01,672] {local_task_job.py:103} INFO - Task exited with return code 1
[2020-06-28 20:31:33,550] {taskinstance.py:669} INFO - Dependencies all met for <TaskInstance: covid_stats.validate_and_clean_data 2020-06-27T00:00:00+00:00 [queued]>
[2020-06-28 20:31:33,561] {taskinstance.py:669} INFO - Dependencies all met for <TaskInstance: covid_stats.validate_and_clean_data 2020-06-27T00:00:00+00:00 [queued]>
[2020-06-28 20:31:33,561] {taskinstance.py:879} INFO - 
--------------------------------------------------------------------------------
[2020-06-28 20:31:33,561] {taskinstance.py:880} INFO - Starting attempt 6 of 6
[2020-06-28 20:31:33,561] {taskinstance.py:881} INFO - 
--------------------------------------------------------------------------------
[2020-06-28 20:31:33,568] {taskinstance.py:900} INFO - Executing <Task(PythonOperator): validate_and_clean_data> on 2020-06-27T00:00:00+00:00
[2020-06-28 20:31:33,570] {standard_task_runner.py:53} INFO - Started process 16961 to run task
[2020-06-28 20:31:33,608] {logging_mixin.py:112} INFO - Running %s on host %s <TaskInstance: covid_stats.validate_and_clean_data 2020-06-27T00:00:00+00:00 [running]> nineleaps-ThinkPad-E480
[2020-06-28 20:31:33,621] {taskinstance.py:1145} ERROR - 'date'
Traceback (most recent call last):
  File "/home/nineleaps/.local/lib/python2.7/site-packages/airflow/models/taskinstance.py", line 983, in _run_raw_task
    result = task_copy.execute(context=context)
  File "/home/nineleaps/.local/lib/python2.7/site-packages/airflow/operators/python_operator.py", line 113, in execute
    return_value = self.execute_callable()
  File "/home/nineleaps/.local/lib/python2.7/site-packages/airflow/operators/python_operator.py", line 118, in execute_callable
    return self.python_callable(*self.op_args, **self.op_kwargs)
  File "/home/nineleaps/airflow/plugins/validate_and_clean_data.py", line 30, in validate_and_clean_data
    pandas_df['date'] = pd.to_datetime(pandas_df['date'], format="%d-%b-%y").dt.date
  File "/home/nineleaps/.local/lib/python2.7/site-packages/pandas/core/frame.py", line 2927, in __getitem__
    indexer = self.columns.get_loc(key)
  File "/home/nineleaps/.local/lib/python2.7/site-packages/pandas/core/indexes/base.py", line 2659, in get_loc
    return self._engine.get_loc(self._maybe_cast_indexer(key))
  File "pandas/_libs/index.pyx", line 108, in pandas._libs.index.IndexEngine.get_loc
  File "pandas/_libs/index.pyx", line 132, in pandas._libs.index.IndexEngine.get_loc
  File "pandas/_libs/hashtable_class_helper.pxi", line 1601, in pandas._libs.hashtable.PyObjectHashTable.get_item
  File "pandas/_libs/hashtable_class_helper.pxi", line 1608, in pandas._libs.hashtable.PyObjectHashTable.get_item
KeyError: 'date'
[2020-06-28 20:31:33,624] {taskinstance.py:1187} INFO - All retries failed; marking task as FAILED.dag_id=covid_stats, task_id=validate_and_clean_data, execution_date=20200627T000000, start_date=20200628T150133, end_date=20200628T150133
[2020-06-28 20:31:43,552] {logging_mixin.py:112} INFO - [2020-06-28 20:31:43,551] {local_task_job.py:103} INFO - Task exited with return code 1
[2020-06-29 11:30:30,599] {taskinstance.py:669} INFO - Dependencies all met for <TaskInstance: covid_stats.validate_and_clean_data 2020-06-27T00:00:00+00:00 [queued]>
[2020-06-29 11:30:30,608] {taskinstance.py:669} INFO - Dependencies all met for <TaskInstance: covid_stats.validate_and_clean_data 2020-06-27T00:00:00+00:00 [queued]>
[2020-06-29 11:30:30,608] {taskinstance.py:879} INFO - 
--------------------------------------------------------------------------------
[2020-06-29 11:30:30,608] {taskinstance.py:880} INFO - Starting attempt 6 of 6
[2020-06-29 11:30:30,608] {taskinstance.py:881} INFO - 
--------------------------------------------------------------------------------
[2020-06-29 11:30:30,615] {taskinstance.py:900} INFO - Executing <Task(PythonOperator): validate_and_clean_data> on 2020-06-27T00:00:00+00:00
[2020-06-29 11:30:30,617] {standard_task_runner.py:53} INFO - Started process 8501 to run task
[2020-06-29 11:30:30,660] {logging_mixin.py:112} INFO - Running %s on host %s <TaskInstance: covid_stats.validate_and_clean_data 2020-06-27T00:00:00+00:00 [running]> nineleaps-ThinkPad-E480
[2020-06-29 11:30:30,675] {taskinstance.py:1145} ERROR - 'date'
Traceback (most recent call last):
  File "/home/nineleaps/.local/lib/python2.7/site-packages/airflow/models/taskinstance.py", line 983, in _run_raw_task
    result = task_copy.execute(context=context)
  File "/home/nineleaps/.local/lib/python2.7/site-packages/airflow/operators/python_operator.py", line 113, in execute
    return_value = self.execute_callable()
  File "/home/nineleaps/.local/lib/python2.7/site-packages/airflow/operators/python_operator.py", line 118, in execute_callable
    return self.python_callable(*self.op_args, **self.op_kwargs)
  File "/home/nineleaps/airflow/plugins/validate_and_clean_data.py", line 30, in validate_and_clean_data
    pandas_df['date'] = pd.to_datetime(pandas_df['date'], format="%d-%b-%y").dt.date
  File "/home/nineleaps/.local/lib/python2.7/site-packages/pandas/core/frame.py", line 2927, in __getitem__
    indexer = self.columns.get_loc(key)
  File "/home/nineleaps/.local/lib/python2.7/site-packages/pandas/core/indexes/base.py", line 2659, in get_loc
    return self._engine.get_loc(self._maybe_cast_indexer(key))
  File "pandas/_libs/index.pyx", line 108, in pandas._libs.index.IndexEngine.get_loc
  File "pandas/_libs/index.pyx", line 132, in pandas._libs.index.IndexEngine.get_loc
  File "pandas/_libs/hashtable_class_helper.pxi", line 1601, in pandas._libs.hashtable.PyObjectHashTable.get_item
  File "pandas/_libs/hashtable_class_helper.pxi", line 1608, in pandas._libs.hashtable.PyObjectHashTable.get_item
KeyError: 'date'
[2020-06-29 11:30:30,678] {taskinstance.py:1187} INFO - All retries failed; marking task as FAILED.dag_id=covid_stats, task_id=validate_and_clean_data, execution_date=20200627T000000, start_date=20200629T060030, end_date=20200629T060030
[2020-06-29 11:30:40,602] {logging_mixin.py:112} INFO - [2020-06-29 11:30:40,601] {local_task_job.py:103} INFO - Task exited with return code 1
